Workbook

Sheet 計測統計
Y1: 單位 | Z1: 公差 | AA1: 工號 | AB1: 品檢員
B2: 品質檢驗紀錄 | Y2: Ø | Z2: - | AA2: 1478 | AB2: 徐澤美 | AC2: V | AD2: 首件 | AE2: ※若內背一起加工，輸入OK | AH2: 遊標卡尺 | AJ2: EFGP
Y3: \ / | Z3: 0 | AA3: 1626 | AB3: 洪士偉 | AD3: 巡檢 | AH3: 2.5D影像量測儀 | AJ3: RD暫存區
B4: 料號 | E4: 804LY0241001B0 | U4: 加工圖 | Y4: # | Z4: 0.005 | AA4: 1650 | AB4: 林銘坤 | AD4: MARCO | AH4: 高度規
B5: 總檢驗數 | E5: =E7+E9+E8 -> 0 | Y5: 距離 | Z5: 0.01 | AA5: 1666 | AB5: 林嘉宏 | AC5: 去牙 | AH5: 螺紋塞規
A6: =COUNTA(E26:E82) -> 53 | B6: 未完檢驗數 | E6: =IF(A6-E5<=0,0,A6-E5) -> 53 | U6: 檢規 | Y6: 深度 | Z6: 0.015 | AA6: 2051 | AB6: 簡凱帆 | AC6: 攻牙 | AH6: 銷規
B7: 檢驗合格 | E7: =COUNTIF(P:P,"合格") -> 0 | Y7: 厚度 | Z7: 0.02 | AA7: 1492 | AB7: 陳思明 | AC7: 植牙套 | AH7: 三次元
B8: 檢驗特採 | E8: =COUNTIF(P:P,"特採") -> 0 | Y8: 外型 | Z8: 0.021 | AA8: 1907 | AB8: 蘇桑托 | AC8: 重工 | AH8: 瞬檢機
B9: 檢驗異常 | E9: =COUNTIF(P:P,"異常") -> 0 | Y9: X | Z9: 0.027 | AA9: 1032 | AB9: 里瓦多 | AC9: 面銑/見光 | AH9: 目視
B10: 機台號碼 | Y10: Y | Z10: 0.027 | AA10: 2011 | AB10: 艾古 | AC10: LOAD | AH10: 分厘卡
B11: 工單號碼 | Y11: 平面 | Z11: 0.03 | AA11: 2037 | AB11: 賽多 | AH11: 厚薄規
B12: 檢驗日期 | Y12: 對稱 | Z12: 0.06 | AA12: 2139 | AB12: 蔡玉婷 | AH12: 表面粗糙度測定儀
B13: 檢驗員 | Y13: 粗糙 | Z13: 0.04 | AA13: 2206 | AB13: 文廷炳 | AH13: R角規
B14: 檢驗類別 | Y14: 刻字 | Z14: 0.05 | AA14: 1925 | AB14: 安瓦
B15: 幹部確認 | D15: 檢驗製程 | E15: 001 | Y15: C | Z15: 0.1 | AA15: 2253 | AB15: 亨奇
E16: 002 | Y16: ◎ | Z16: 0.15 | AA16: 2297 | AB16: 黎庭光
E17: 003 | Y17: ⊕ | Z17: 0.2 | AA17: 2302 | AB17: 李佳駿
E18: 004 | Y18: R | Z18: 0.4 | AA18: 2328 | AB18: 蘇玉美
E19: 005 | Y19: Z | Z19: 0.5 | AA19: 2170 | AB19: 倪震皓
E20: 006 | Y20: D.P. | Z20: 0.8 | AA20: 1200 | AB20: 趙茹涵
E21: 007 | Y21: M | Z21: 0.25 | AA21: 2131 | AB21: 李楨儀
E22: 008 | Y22: 度 | Z22: 0.14 | AA22: 2248 | AB22: 王健宇
E23: 009 | Y23: 牙深 | Z23: 2
E24: 010 | Y24: 高度
B25: 製程 | C25: 檢點 | D25: 檢驗標準(單位mm) | K25: 自動2.5D設備數據 | L25: 判定 | M25: 手動量測 | N25: 覆檢 | O25: 再覆檢 | P25: 判定 | Q25: 檢驗備註 組長特採 | S25: 儀器 | Y25: 孔深
B26: 001 | C26: 1 | D26: 距離 | E26: 70 | G26: + | H26: 0.1 | I26: - | J26: 0.1 | K26: =IF(ISERROR(VLOOKUP(C26,DATA!A:I,7,FALSE))=TRUE,"",VLOOKUP(C26,DATA!A:I,7,FALSE)) | L26: =IF(OR(D26="刻字",K26="",D26="M",D26="#",D26="粗糙",D26="平面",E26="THRU"),"待驗",IF(AND(K26<=E26+(H26*0.66),K26>=E26-(J26*0.66)),"合格",IF(AND(K26<=E26+H26,K26>=E26-J26),"特採","異常"))) -> 待驗 | P26: =IF(AND(K26="",M26="",N26=""),"待驗",IF(OR(L26="合格",L26="特採"),L26,IFERROR(IF(AND(D26="刻字",OR(M26=E26,N26=E26,)),"合格",IF(OR(M26="OK",N26="OK"),"合格",IF(OR(AND(M26<=E26+(H26*0.66),M26>=E26-(J26*0.66)),AND(N26<=E26+(H26*0.66),N26>=E26-(J26*0.66)),AND(O26<=E26+(H26*0.66),O26>=E26-(J26*0.66))),"合格",IF(OR(AND(M26<=E26+H26,M26>=E26-J26),AND(N26<=E26+H26,N26>=E26-J26)),"特採","異常")))),"異常"))) -> 待驗 | S26: 2.5D影像量測儀 | Y26: 輪廓度 | Z26: -
B27: 001 | C27: 2 | D27: 距離 | E27: 54 | G27: + | H27: 0.1 | I27: - | J27: 0.1 | K27: =IF(ISERROR(VLOOKUP(C27,DATA!A:I,7,FALSE))=TRUE,"",VLOOKUP(C27,DATA!A:I,7,FALSE)) | L27: =IF(OR(D27="刻字",K27="",D27="M",D27="#",D27="粗糙",D27="平面",E27="THRU"),"待驗",IF(AND(K27<=E27+(H27*0.66),K27>=E27-(J27*0.66)),"合格",IF(AND(K27<=E27+H27,K27>=E27-J27),"特採","異常"))) -> 待驗 | P27: =IF(AND(K27="",M27="",N27=""),"待驗",IF(OR(L27="合格",L27="特採"),L27,IFERROR(IF(AND(D27="刻字",OR(M27=E27,N27=E27,)),"合格",IF(OR(M27="OK",N27="OK"),"合格",IF(OR(AND(M27<=E27+(H27*0.66),M27>=E27-(J27*0.66)),AND(N27<=E27+(H27*0.66),N27>=E27-(J27*0.66)),AND(O27<=E27+(H27*0.66),O27>=E27-(J27*0.66))),"合格",IF(OR(AND(M27<=E27+H27,M27>=E27-J27),AND(N27<=E27+H27,N27>=E27-J27)),"特採","異常")))),"異常"))) -> 待驗 | S27: 2.5D影像量測儀 | Y27: —
B28: 001 | C28: 3 | D28: 距離 | E28: 42 | G28: + | H28: 0.1 | I28: - | J28: 0.1 | K28: =IF(ISERROR(VLOOKUP(C28,DATA!A:I,7,FALSE))=TRUE,"",VLOOKUP(C28,DATA!A:I,7,FALSE)) | L28: =IF(OR(D28="刻字",K28="",D28="M",D28="#",D28="粗糙",D28="平面",E28="THRU"),"待驗",IF(AND(K28<=E28+(H28*0.66),K28>=E28-(J28*0.66)),"合格",IF(AND(K28<=E28+H28,K28>=E28-J28),"特採","異常"))) -> 待驗 | P28: =IF(AND(K28="",M28="",N28=""),"待驗",IF(OR(L28="合格",L28="特採"),L28,IFERROR(IF(AND(D28="刻字",OR(M28=E28,N28=E28,)),"合格",IF(OR(M28="OK",N28="OK"),"合格",IF(OR(AND(M28<=E28+(H28*0.66),M28>=E28-(J28*0.66)),AND(N28<=E28+(H28*0.66),N28>=E28-(J28*0.66)),AND(O28<=E28+(H28*0.66),O28>=E28-(J28*0.66))),"合格",IF(OR(AND(M28<=E28+H28,M28>=E28-J28),AND(N28<=E28+H28,N28>=E28-J28)),"特採","異常")))),"異常"))) -> 待驗 | S28: 2.5D影像量測儀 | Y28: ⊥ | AB28: 謝博安
B29: 001 | C29: 4 | D29: 深度 | E29: 28.4 | G29: + | H29: 0.05 | I29: - | J29: 0.05 | K29: =IF(ISERROR(VLOOKUP(C29,DATA!A:I,7,FALSE))=TRUE,"",VLOOKUP(C29,DATA!A:I,7,FALSE)) | L29: =IF(OR(D29="刻字",K29="",D29="M",D29="#",D29="粗糙",D29="平面",E29="THRU"),"待驗",IF(AND(K29<=E29+(H29*0.66),K29>=E29-(J29*0.66)),"合格",IF(AND(K29<=E29+H29,K29>=E29-J29),"特採","異常"))) -> 待驗 | P29: =IF(AND(K29="",M29="",N29=""),"待驗",IF(OR(L29="合格",L29="特採"),L29,IFERROR(IF(AND(D29="刻字",OR(M29=E29,N29=E29,)),"合格",IF(OR(M29="OK",N29="OK"),"合格",IF(OR(AND(M29<=E29+(H29*0.66),M29>=E29-(J29*0.66)),AND(N29<=E29+(H29*0.66),N29>=E29-(J29*0.66)),AND(O29<=E29+(H29*0.66),O29>=E29-(J29*0.66))),"合格",IF(OR(AND(M29<=E29+H29,M29>=E29-J29),AND(N29<=E29+H29,N29>=E29-J29)),"特採","異常")))),"異常"))) -> 待驗 | S29: 2.5D影像量測儀 | AB29: 莊志南
B30: 001 | C30: 5 | D30: # | E30: 4-40 UNJC-3B | G30: + | H30: - | I30: - | J30: - | K30: =IF(ISERROR(VLOOKUP(C30,DATA!A:I,7,FALSE))=TRUE,"",VLOOKUP(C30,DATA!A:I,7,FALSE)) | L30: =IF(OR(D30="刻字",K30="",D30="M",D30="#",D30="粗糙",D30="平面",E30="THRU"),"待驗",IF(AND(K30<=E30+(H30*0.66),K30>=E30-(J30*0.66)),"合格",IF(AND(K30<=E30+H30,K30>=E30-J30),"特採","異常"))) -> 待驗 | P30: =IF(AND(K30="",M30="",N30=""),"待驗",IF(OR(L30="合格",L30="特採"),L30,IFERROR(IF(AND(D30="刻字",OR(M30=E30,N30=E30,)),"合格",IF(OR(M30="OK",N30="OK"),"合格",IF(OR(AND(M30<=E30+(H30*0.66),M30>=E30-(J30*0.66)),AND(N30<=E30+(H30*0.66),N30>=E30-(J30*0.66)),AND(O30<=E30+(H30*0.66),O30>=E30-(J30*0.66))),"合格",IF(OR(AND(M30<=E30+H30,M30>=E30-J30),AND(N30<=E30+H30,N30>=E30-J30)),"特採","異常")))),"異常"))) -> 待驗 | S30: 螺紋塞規 | AB30: 張耀隆
B31: 001 | C31: 5 | D31: 牙深 | E31: 7.5 | G31: + | H31: 0.5 | I31: - | J31: 0.1 | K31: =IF(ISERROR(VLOOKUP(C31,DATA!A:I,7,FALSE))=TRUE,"",VLOOKUP(C31,DATA!A:I,7,FALSE)) | L31: =IF(OR(D31="刻字",K31="",D31="M",D31="#",D31="粗糙",D31="平面",E31="THRU"),"待驗",IF(AND(K31<=E31+(H31*0.66),K31>=E31-(J31*0.66)),"合格",IF(AND(K31<=E31+H31,K31>=E31-J31),"特採","異常"))) -> 待驗 | P31: =IF(AND(K31="",M31="",N31=""),"待驗",IF(OR(L31="合格",L31="特採"),L31,IFERROR(IF(AND(D31="刻字",OR(M31=E31,N31=E31,)),"合格",IF(OR(M31="OK",N31="OK"),"合格",IF(OR(AND(M31<=E31+(H31*0.66),M31>=E31-(J31*0.66)),AND(N31<=E31+(H31*0.66),N31>=E31-(J31*0.66)),AND(O31<=E31+(H31*0.66),O31>=E31-(J31*0.66))),"合格",IF(OR(AND(M31<=E31+H31,M31>=E31-J31),AND(N31<=E31+H31,N31>=E31-J31)),"特採","異常")))),"異常"))) -> 待驗 | S31: 螺紋塞規 | AB31: 余楷祥
B32: 001 | C32: 5 | E32: 檢查不可破孔 | G32: + | H32: - | I32: - | J32: - | K32: =IF(ISERROR(VLOOKUP(C32,DATA!A:I,7,FALSE))=TRUE,"",VLOOKUP(C32,DATA!A:I,7,FALSE)) | L32: =IF(OR(D32="刻字",K32="",D32="M",D32="#",D32="粗糙",D32="平面",E32="THRU"),"待驗",IF(AND(K32<=E32+(H32*0.66),K32>=E32-(J32*0.66)),"合格",IF(AND(K32<=E32+H32,K32>=E32-J32),"特採","異常"))) -> 待驗 | P32: =IF(AND(K32="",M32="",N32=""),"待驗",IF(OR(L32="合格",L32="特採"),L32,IFERROR(IF(AND(D32="刻字",OR(M32=E32,N32=E32,)),"合格",IF(OR(M32="OK",N32="OK"),"合格",IF(OR(AND(M32<=E32+(H32*0.66),M32>=E32-(J32*0.66)),AND(N32<=E32+(H32*0.66),N32>=E32-(J32*0.66)),AND(O32<=E32+(H32*0.66),O32>=E32-(J32*0.66))),"合格",IF(OR(AND(M32<=E32+H32,M32>=E32-J32),AND(N32<=E32+H32,N32>=E32-J32)),"特採","異常")))),"異常"))) -> 待驗 | S32: 目視 | AB32: 洪國信
B33: 001 | C33: 6 | D33: 距離 | E33: 30.5 | G33: + | H33: 0.05 | I33: - | J33: 0.02 | K33: =IF(ISERROR(VLOOKUP(C33,DATA!A:I,7,FALSE))=TRUE,"",VLOOKUP(C33,DATA!A:I,7,FALSE)) | L33: =IF(OR(D33="刻字",K33="",D33="M",D33="#",D33="粗糙",D33="平面",E33="THRU"),"待驗",IF(AND(K33<=E33+(H33*0.66),K33>=E33-(J33*0.66)),"合格",IF(AND(K33<=E33+H33,K33>=E33-J33),"特採","異常"))) -> 待驗 | P33: =IF(AND(K33="",M33="",N33=""),"待驗",IF(OR(L33="合格",L33="特採"),L33,IFERROR(IF(AND(D33="刻字",OR(M33=E33,N33=E33,)),"合格",IF(OR(M33="OK",N33="OK"),"合格",IF(OR(AND(M33<=E33+(H33*0.66),M33>=E33-(J33*0.66)),AND(N33<=E33+(H33*0.66),N33>=E33-(J33*0.66)),AND(O33<=E33+(H33*0.66),O33>=E33-(J33*0.66))),"合格",IF(OR(AND(M33<=E33+H33,M33>=E33-J33),AND(N33<=E33+H33,N33>=E33-J33)),"特採","異常")))),"異常"))) -> 待驗 | S33: 2.5D影像量測儀 | AB33: 泰沙
B34: 001 | C34: 7 | E34: 31 | G34: + | H34: 0.05 | I34: - | J34: 0.05 | K34: =IF(ISERROR(VLOOKUP(C34,DATA!A:I,7,FALSE))=TRUE,"",VLOOKUP(C34,DATA!A:I,7,FALSE)) | L34: =IF(OR(D34="刻字",K34="",D34="M",D34="#",D34="粗糙",D34="平面",E34="THRU"),"待驗",IF(AND(K34<=E34+(H34*0.66),K34>=E34-(J34*0.66)),"合格",IF(AND(K34<=E34+H34,K34>=E34-J34),"特採","異常"))) -> 待驗 | P34: =IF(AND(K34="",M34="",N34=""),"待驗",IF(OR(L34="合格",L34="特採"),L34,IFERROR(IF(AND(D34="刻字",OR(M34=E34,N34=E34,)),"合格",IF(OR(M34="OK",N34="OK"),"合格",IF(OR(AND(M34<=E34+(H34*0.66),M34>=E34-(J34*0.66)),AND(N34<=E34+(H34*0.66),N34>=E34-(J34*0.66)),AND(O34<=E34+(H34*0.66),O34>=E34-(J34*0.66))),"合格",IF(OR(AND(M34<=E34+H34,M34>=E34-J34),AND(N34<=E34+H34,N34>=E34-J34)),"特採","異常")))),"異常"))) -> 待驗 | S34: 2.5D影像量測儀
B35: 001 | C35: 8 | D35: Ø | E35: 1.6 | G35: + | H35: 0.05 | I35: - | J35: 0 | K35: =IF(ISERROR(VLOOKUP(C35,DATA!A:I,7,FALSE))=TRUE,"",VLOOKUP(C35,DATA!A:I,7,FALSE)) | L35: =IF(OR(D35="刻字",K35="",D35="M",D35="#",D35="粗糙",D35="平面",E35="THRU"),"待驗",IF(AND(K35<=E35+(H35*0.66),K35>=E35-(J35*0.66)),"合格",IF(AND(K35<=E35+H35,K35>=E35-J35),"特採","異常"))) -> 待驗 | P35: =IF(AND(K35="",M35="",N35=""),"待驗",IF(OR(L35="合格",L35="特採"),L35,IFERROR(IF(AND(D35="刻字",OR(M35=E35,N35=E35,)),"合格",IF(OR(M35="OK",N35="OK"),"合格",IF(OR(AND(M35<=E35+(H35*0.66),M35>=E35-(J35*0.66)),AND(N35<=E35+(H35*0.66),N35>=E35-(J35*0.66)),AND(O35<=E35+(H35*0.66),O35>=E35-(J35*0.66))),"合格",IF(OR(AND(M35<=E35+H35,M35>=E35-J35),AND(N35<=E35+H35,N35>=E35-J35)),"特採","異常")))),"異常"))) -> 待驗 | S35: 2.5D影像量測儀
B36: 001 | C36: 9 | D36: # | E36: 4-40 UNJC-3B | G36: + | H36: - | I36: - | J36: - | K36: =IF(ISERROR(VLOOKUP(C36,DATA!A:I,7,FALSE))=TRUE,"",VLOOKUP(C36,DATA!A:I,7,FALSE)) | L36: =IF(OR(D36="刻字",K36="",D36="M",D36="#",D36="粗糙",D36="平面",E36="THRU"),"待驗",IF(AND(K36<=E36+(H36*0.66),K36>=E36-(J36*0.66)),"合格",IF(AND(K36<=E36+H36,K36>=E36-J36),"特採","異常"))) -> 待驗 | P36: =IF(AND(K36="",M36="",N36=""),"待驗",IF(OR(L36="合格",L36="特採"),L36,IFERROR(IF(AND(D36="刻字",OR(M36=E36,N36=E36,)),"合格",IF(OR(M36="OK",N36="OK"),"合格",IF(OR(AND(M36<=E36+(H36*0.66),M36>=E36-(J36*0.66)),AND(N36<=E36+(H36*0.66),N36>=E36-(J36*0.66)),AND(O36<=E36+(H36*0.66),O36>=E36-(J36*0.66))),"合格",IF(OR(AND(M36<=E36+H36,M36>=E36-J36),AND(N36<=E36+H36,N36>=E36-J36)),"特採","異常")))),"異常"))) -> 待驗 | S36: 螺紋塞規
B37: 001 | C37: 9 | D37: 牙深 | E37: 8 | G37: + | H37: 0.5 | I37: - | J37: 0.1 | K37: =IF(ISERROR(VLOOKUP(C37,DATA!A:I,7,FALSE))=TRUE,"",VLOOKUP(C37,DATA!A:I,7,FALSE)) | L37: =IF(OR(D37="刻字",K37="",D37="M",D37="#",D37="粗糙",D37="平面",E37="THRU"),"待驗",IF(AND(K37<=E37+(H37*0.66),K37>=E37-(J37*0.66)),"合格",IF(AND(K37<=E37+H37,K37>=E37-J37),"特採","異常"))) -> 待驗 | P37: =IF(AND(K37="",M37="",N37=""),"待驗",IF(OR(L37="合格",L37="特採"),L37,IFERROR(IF(AND(D37="刻字",OR(M37=E37,N37=E37,)),"合格",IF(OR(M37="OK",N37="OK"),"合格",IF(OR(AND(M37<=E37+(H37*0.66),M37>=E37-(J37*0.66)),AND(N37<=E37+(H37*0.66),N37>=E37-(J37*0.66)),AND(O37<=E37+(H37*0.66),O37>=E37-(J37*0.66))),"合格",IF(OR(AND(M37<=E37+H37,M37>=E37-J37),AND(N37<=E37+H37,N37>=E37-J37)),"特採","異常")))),"異常"))) -> 待驗 | S37: 螺紋塞規
B38: 001 | C38: 10 | D38: Ø | E38: 6 | G38: + | H38: 0.05 | I38: - | J38: 0.05 | K38: =IF(ISERROR(VLOOKUP(C38,DATA!A:I,7,FALSE))=TRUE,"",VLOOKUP(C38,DATA!A:I,7,FALSE)) | L38: =IF(OR(D38="刻字",K38="",D38="M",D38="#",D38="粗糙",D38="平面",E38="THRU"),"待驗",IF(AND(K38<=E38+(H38*0.66),K38>=E38-(J38*0.66)),"合格",IF(AND(K38<=E38+H38,K38>=E38-J38),"特採","異常"))) -> 待驗 | P38: =IF(AND(K38="",M38="",N38=""),"待驗",IF(OR(L38="合格",L38="特採"),L38,IFERROR(IF(AND(D38="刻字",OR(M38=E38,N38=E38,)),"合格",IF(OR(M38="OK",N38="OK"),"合格",IF(OR(AND(M38<=E38+(H38*0.66),M38>=E38-(J38*0.66)),AND(N38<=E38+(H38*0.66),N38>=E38-(J38*0.66)),AND(O38<=E38+(H38*0.66),O38>=E38-(J38*0.66))),"合格",IF(OR(AND(M38<=E38+H38,M38>=E38-J38),AND(N38<=E38+H38,N38>=E38-J38)),"特採","異常")))),"異常"))) -> 待驗 | Q38: 6.0GO/6.03NOGO | S38: 銷規
B39: 001 | C39: 10 | E39: THRU | G39: + | H39: - | I39: - | J39: - | K39: =IF(ISERROR(VLOOKUP(C39,DATA!A:I,7,FALSE))=TRUE,"",VLOOKUP(C39,DATA!A:I,7,FALSE)) | L39: =IF(OR(D39="刻字",K39="",D39="M",D39="#",D39="粗糙",D39="平面",E39="THRU"),"待驗",IF(AND(K39<=E39+(H39*0.66),K39>=E39-(J39*0.66)),"合格",IF(AND(K39<=E39+H39,K39>=E39-J39),"特採","異常"))) -> 待驗 | P39: =IF(AND(K39="",M39="",N39=""),"待驗",IF(OR(L39="合格",L39="特採"),L39,IFERROR(IF(AND(D39="刻字",OR(M39=E39,N39=E39,)),"合格",IF(OR(M39="OK",N39="OK"),"合格",IF(OR(AND(M39<=E39+(H39*0.66),M39>=E39-(J39*0.66)),AND(N39<=E39+(H39*0.66),N39>=E39-(J39*0.66)),AND(O39<=E39+(H39*0.66),O39>=E39-(J39*0.66))),"合格",IF(OR(AND(M39<=E39+H39,M39>=E39-J39),AND(N39<=E39+H39,N39>=E39-J39)),"特採","異常")))),"異常"))) -> 待驗 | S39: 銷規
B40: 001 | C40: 11 | D40: M | E40: 8X1.25 | G40: + | H40: 0.01 | I40: - | J40: 0.01 | K40: =IF(ISERROR(VLOOKUP(C40,DATA!A:I,7,FALSE))=TRUE,"",VLOOKUP(C40,DATA!A:I,7,FALSE)) | L40: =IF(OR(D40="刻字",K40="",D40="M",D40="#",D40="粗糙",D40="平面",E40="THRU"),"待驗",IF(AND(K40<=E40+(H40*0.66),K40>=E40-(J40*0.66)),"合格",IF(AND(K40<=E40+H40,K40>=E40-J40),"特採","異常"))) -> 待驗 | P40: =IF(AND(K40="",M40="",N40=""),"待驗",IF(OR(L40="合格",L40="特採"),L40,IFERROR(IF(AND(D40="刻字",OR(M40=E40,N40=E40,)),"合格",IF(OR(M40="OK",N40="OK"),"合格",IF(OR(AND(M40<=E40+(H40*0.66),M40>=E40-(J40*0.66)),AND(N40<=E40+(H40*0.66),N40>=E40-(J40*0.66)),AND(O40<=E40+(H40*0.66),O40>=E40-(J40*0.66))),"合格",IF(OR(AND(M40<=E40+H40,M40>=E40-J40),AND(N40<=E40+H40,N40>=E40-J40)),"特採","異常")))),"異常"))) -> 待驗 | S40: 螺紋塞規
...

Sheet DATA
B1: FeatureType | C1: FeatureLabel | D1: FeatureID | E1: OutputItem | F1: Actual | G1: Nominal | H1: Deviation | I1: UpperTol | J1: LowerTol | K1: PassFail
A2: =SUBSTITUTE(SUBSTITUTE(SUBSTITUTE(SUBSTITUTE(SUBSTITUTE(C2,"檢點",""),"[1",""),"Z0",""),"-",""),"原點","")
A3: =SUBSTITUTE(SUBSTITUTE(SUBSTITUTE(SUBSTITUTE(SUBSTITUTE(C3,"檢點",""),"[1",""),"Z0",""),"-",""),"原點","")
A4: =SUBSTITUTE(SUBSTITUTE(SUBSTITUTE(SUBSTITUTE(SUBSTITUTE(C4,"檢點",""),"[1",""),"Z0",""),"-",""),"原點","")
A5: =SUBSTITUTE(SUBSTITUTE(SUBSTITUTE(SUBSTITUTE(SUBSTITUTE(C5,"檢點",""),"[1",""),"Z0",""),"-",""),"原點","")
A6: =SUBSTITUTE(SUBSTITUTE(SUBSTITUTE(SUBSTITUTE(SUBSTITUTE(C6,"檢點",""),"[1",""),"Z0",""),"-",""),"原點","")
A7: =SUBSTITUTE(SUBSTITUTE(SUBSTITUTE(SUBSTITUTE(SUBSTITUTE(C7,"檢點",""),"[1",""),"Z0",""),"-",""),"原點","")
A8: =SUBSTITUTE(SUBSTITUTE(SUBSTITUTE(SUBSTITUTE(SUBSTITUTE(C8,"檢點",""),"[1",""),"Z0",""),"-",""),"原點","")
A9: =SUBSTITUTE(SUBSTITUTE(SUBSTITUTE(SUBSTITUTE(SUBSTITUTE(C9,"檢點",""),"[1",""),"Z0",""),"-",""),"原點","")
A10: =SUBSTITUTE(SUBSTITUTE(SUBSTITUTE(SUBSTITUTE(SUBSTITUTE(C10,"檢點",""),"[1",""),"Z0",""),"-",""),"原點","")
A11: =SUBSTITUTE(SUBSTITUTE(SUBSTITUTE(SUBSTITUTE(SUBSTITUTE(C11,"檢點",""),"[1",""),"Z0",""),"-",""),"原點","")
A12: =SUBSTITUTE(SUBSTITUTE(SUBSTITUTE(SUBSTITUTE(SUBSTITUTE(C12,"檢點",""),"[1",""),"Z0",""),"-",""),"原點","")
A13: =SUBSTITUTE(SUBSTITUTE(SUBSTITUTE(SUBSTITUTE(SUBSTITUTE(C13,"檢點",""),"[1",""),"Z0",""),"-",""),"原點","")
... A70: =SUBSTITUTE(SUBSTITUTE(SUBSTITUTE(SUBSTITUTE(SUBSTITUTE(C70,"檢點",""),"[1",""),"Z0",""),"-",""),"原點","")

Sheet 更新履歷
B2: 更新履歷
B3: 項次 | C3: 更新內容 | D3: 更新日期 | E3: 更新人
B4: 1 | C4: 數位量測電子檔建立，做為數位設備導入時，自動計算數據的範本 | D4: 44218 | E4: 褚宏淯
B5: 2 | C5: 1.新增單位、公差的下拉式選單，加快建置表單時的速度 2.建立DATA活頁，可將自動2.5D量測數據倒入，資料整合彙整時可以使用 | D5: 44235 | E5: 褚宏淯
B6: 3 | C6: 於判定列N、P、R的函數，新增OR指令，修正輸入文字NG時，函數無反應跳錯的現象。 | D6: 44245 | E6: 褚宏淯
B7: 4 | C7: 已完成的檔案，將同步進行下列修正: 1.移除自動2.5D的判定，重新撰寫程式，使自動量測&手動量測共用一個判定。 2.重新編排刻字的驗證方式，人員完整輸入工件刻字，確認是否相符 3.重新調整D.P.的公差設定，正常工差為±0.2mm，只深不淺的公差該為+0.5/-0mm | D7: 44274 | E7: 褚宏淯
B8: 5 | C8: 為提醒生產加工需調機，調整函數及版面格式對應: 1. 判定由3列改為1列，減少人員判定看錯的風險 2. 增加再複驗欄位，避免第2次調機複檢，沒有地方填寫 3. 判定的地方修改反饋內容，由”OK”，”NG”調整如下 →合格:尺寸符合規範，不用進行調整 →異常:尺寸超出規範，要進行調整 →特採:尺寸合格，但已接近標準差的極限，請組長確認是否進行調整 →待驗:尺寸沒有檢驗，請進行檢驗確認 4. 加大檢驗備註，組長特採欄位，方便人員記錄異常，及組長簽名 | D8: 44771 | E8: 褚宏淯
B9: 6 | C9: 1.修正P列，函數判斷錯誤，輸入"NG"不會判定異常 2.取消P列"合格"的底色填滿，避免列印紙本給組長時，跟"異常"相同的呈現方式，不易辨別。 3.將L、P列的函數，由原本47個增加到100個，避免新增數位量測程式時，函數不足人員不會自行新增。 | D9: 44802 | E9: 褚宏淯
B10: 7
B11: 8
B12: 9
B13: 10

Sheet 異常圖片
C28: 跳回 | D28: 計測統計!A1
